Workbook

Sheet Oracle_Review
A1: Independent verification: synthetic disposable committed Runs; no commercial default rates
A2: BASE CFADS rebuilt from persisted statement EBITDA + financing income - cash tax.
A3: BANK CFADS, C1 unlevered components, debt opening and sponsor receipts are engine-derived input evidence.
A4: Formula caches are independently calculated using Decimal(50). Excel recalculates formulas on open.
A5: FIN-V2-2 composition uses exact PR #390 module in disposable test capture only; source branches remain separate.
A7: Case | B7: Metric | C7: Persisted FINCO | D7: Independent oracle | E7: Difference | F7: Run snapshot | G7: Evidence digest
A8: 1_sol_BASE | B8: llcr_contractual_maturity | C8: 1.6807731 | D8: =SUM('1_sol_BASE_Inputs'!N12:N61)/'1_sol_BASE_Inputs'!K12 -> 1.6807731 | E8: =D8-C8 -> -1.110223e-15 | F8: 20261027T142419665354Z | G8: f29bf6421e872ac29a71c948d8472f5fcab1ba27f39b5a1268e00340be30b158
A9: 1_sol_BASE | B9: llcr_actual_repayment | C9: 1.3558183 | D9: =SUM('1_sol_BASE_Inputs'!O12:O61)/'1_sol_BASE_Inputs'!K12 -> 1.3558183 | E9: =D9-C9 -> -6.6613381e-16 | F9: 20261027T142419665354Z | G9: f29bf6421e872ac29a71c948d8472f5fcab1ba27f39b5a1268e00340be30b158
A10: 1_sol_BASE | B10: plcr | C10: 2.4011558 | D10: =SUM('1_sol_BASE_Inputs'!P12:P61)/'1_sol_BASE_Inputs'!K12 -> 2.4011558 | E10: =D10-C10 -> -1.7763568e-15 | F10: 20261027T142419665354Z | G10: f29bf6421e872ac29a71c948d8472f5fcab1ba27f39b5a1268e00340be30b158
A11: 1_sol_BASE | B11: min_rolling_llcr | C11: 1.3553972 | D11: =MIN('1_sol_BASE_Roll'!E2:E24) -> 1.3553972 | E11: =D11-C11 -> -6.6613381e-16 | F11: 20261027T142419665354Z | G11: f29bf6421e872ac29a71c948d8472f5fcab1ba27f39b5a1268e00340be30b158
A12: 1_sol_BASE | B12: project_npv_keur | C12: 12753.772 | D12: =SUM('1_sol_BASE_CF'!G4:G56) -> 12753.772 | E12: =D12-C12 -> 3.092282e-11 | F12: 20261027T142419665354Z | G12: f29bf6421e872ac29a71c948d8472f5fcab1ba27f39b5a1268e00340be30b158
A13: 1_sol_BASE | B13: sponsor_npv_keur | C13: 6181.7123 | D13: =SUM('1_sol_BASE_CF'!O4:O56) -> 6181.7123 | E13: =D13-C13 -> 1.6370905e-11 | F13: 20261027T142419665354Z | G13: f29bf6421e872ac29a71c948d8472f5fcab1ba27f39b5a1268e00340be30b158
A14: 2_sol_BANK | B14: llcr_contractual_maturity | C14: 1.526926 | D14: =SUM('2_sol_BANK_Inputs'!N12:N61)/'2_sol_BANK_Inputs'!K12 -> 1.526926 | E14: =D14-C14 -> -6.6613381e-16 | F14: 20261027T142420977782Z | G14: 9474dc7cb5d31f1a7675af01a064b9349d1a5a170245cf304f68cc6725daf89e
A15: 2_sol_BANK | B15: llcr_actual_repayment | C15: 1.2333445 | D15: =SUM('2_sol_BANK_Inputs'!O12:O61)/'2_sol_BANK_Inputs'!K12 -> 1.2333445 | E15: =D15-C15 -> -6.6613381e-16 | F15: 20261027T142420977782Z | G15: 9474dc7cb5d31f1a7675af01a064b9349d1a5a170245cf304f68cc6725daf89e
A16: 2_sol_BANK | B16: plcr | C16: 2.1738386 | D16: =SUM('2_sol_BANK_Inputs'!P12:P61)/'2_sol_BANK_Inputs'!K12 -> 2.1738386 | E16: =D16-C16 -> -8.8817842e-16 | F16: 20261027T142420977782Z | G16: 9474dc7cb5d31f1a7675af01a064b9349d1a5a170245cf304f68cc6725daf89e
A17: 2_sol_BANK | B17: min_rolling_llcr | C17: 1.2333445 | D17: =MIN('2_sol_BANK_Roll'!E2:E24) -> 1.2333445 | E17: =D17-C17 -> -6.6613381e-16 | F17: 20261027T142420977782Z | G17: 9474dc7cb5d31f1a7675af01a064b9349d1a5a170245cf304f68cc6725daf89e
A18: 2_sol_BANK | B18: project_npv_keur | C18: 12753.772 | D18: =SUM('2_sol_BANK_CF'!G4:G56) -> 12753.772 | E18: =D18-C18 -> 3.092282e-11 | F18: 20261027T142420977782Z | G18: 9474dc7cb5d31f1a7675af01a064b9349d1a5a170245cf304f68cc6725daf89e
A19: 2_sol_BANK | B19: sponsor_npv_keur | C19: 6181.7123 | D19: =SUM('2_sol_BANK_CF'!O4:O56) -> 6181.7123 | E19: =D19-C19 -> 1.6370905e-11 | F19: 20261027T142420977782Z | G19: 9474dc7cb5d31f1a7675af01a064b9349d1a5a170245cf304f68cc6725daf89e
A20: 3_win_BASE | B20: llcr_contractual_maturity | C20: 1.9179978 | D20: =SUM('3_win_BASE_Inputs'!N12:N65)/'3_win_BASE_Inputs'!K12 -> 1.9179978 | E20: =D20-C20 -> -1.5543122e-15 | F20: 20261027T142422605305Z | G20: 37cb0fb5b119e0c07065b92a289050122f6b622ce5e13af115458f8b89fb814c
A21: 3_win_BASE | B21: llcr_actual_repayment | C21: 1.3840496 | D21: =SUM('3_win_BASE_Inputs'!O12:O65)/'3_win_BASE_Inputs'!K12 -> 1.3840496 | E21: =D21-C21 -> -8.8817842e-16 | F21: 20261027T142422605305Z | G21: 37cb0fb5b119e0c07065b92a289050122f6b622ce5e13af115458f8b89fb814c
A22: 3_win_BASE | B22: plcr | C22: 2.8961419 | D22: =SUM('3_win_BASE_Inputs'!P12:P65)/'3_win_BASE_Inputs'!K12 -> 2.8961419 | E22: =D22-C22 -> -3.5527137e-15 | F22: 20261027T142422605305Z | G22: 37cb0fb5b119e0c07065b92a289050122f6b622ce5e13af115458f8b89fb814c
A23: 3_win_BASE | B23: min_rolling_llcr | C23: 1.3840496 | D23: =MIN('3_win_BASE_Roll'!E2:E21) -> 1.3840496 | E23: =D23-C23 -> -8.8817842e-16 | F23: 20261027T142422605305Z | G23: 37cb0fb5b119e0c07065b92a289050122f6b622ce5e13af115458f8b89fb814c
A24: 3_win_BASE | B24: project_npv_keur | C24: 28065.339 | D24: =SUM('3_win_BASE_CF'!G4:G61) -> 28065.339 | E24: =D24-C24 -> 5.8207661e-11 | F24: 20261027T142422605305Z | G24: 37cb0fb5b119e0c07065b92a289050122f6b622ce5e13af115458f8b89fb814c
A25: 3_win_BASE | B25: sponsor_npv_keur | C25: 13450.114 | D25: =SUM('3_win_BASE_CF'!O4:O61) -> 13450.114 | E25: =D25-C25 -> 3.2741809e-11 | F25: 20261027T142422605305Z | G25: 37cb0fb5b119e0c07065b92a289050122f6b622ce5e13af115458f8b89fb814c
A26: 4_win_BANK | B26: llcr_contractual_maturity | C26: 1.7377954 | D26: =SUM('4_win_BANK_Inputs'!N12:N65)/'4_win_BANK_Inputs'!K12 -> 1.7377954 | E26: =D26-C26 -> -6.6613381e-16 | F26: 20261027T142424323930Z | G26: a20e9350fde7107de910716bff2ea92303880a0996b67577bb0d060b03aefb7c
A27: 4_win_BANK | B27: llcr_actual_repayment | C27: 1.2565726 | D27: =SUM('4_win_BANK_Inputs'!O12:O65)/'4_win_BANK_Inputs'!K12 -> 1.2565726 | E27: =D27-C27 -> -2.220446e-16 | F27: 20261027T142424323930Z | G27: a20e9350fde7107de910716bff2ea92303880a0996b67577bb0d060b03aefb7c
A28: 4_win_BANK | B28: plcr | C28: 2.615843 | D28: =SUM('4_win_BANK_Inputs'!P12:P65)/'4_win_BANK_Inputs'!K12 -> 2.615843 | E28: =D28-C28 -> -4.4408921e-16 | F28: 20261027T142424323930Z | G28: a20e9350fde7107de910716bff2ea92303880a0996b67577bb0d060b03aefb7c
A29: 4_win_BANK | B29: min_rolling_llcr | C29: 1.2565726 | D29: =MIN('4_win_BANK_Roll'!E2:E21) -> 1.2565726 | E29: =D29-C29 -> -2.220446e-16 | F29: 20261027T142424323930Z | G29: a20e9350fde7107de910716bff2ea92303880a0996b67577bb0d060b03aefb7c
A30: 4_win_BANK | B30: project_npv_keur | C30: 28065.339 | D30: =SUM('4_win_BANK_CF'!G4:G61) -> 28065.339 | E30: =D30-C30 -> 5.8207661e-11 | F30: 20261027T142424323930Z | G30: a20e9350fde7107de910716bff2ea92303880a0996b67577bb0d060b03aefb7c
A31: 4_win_BANK | B31: sponsor_npv_keur | C31: 13450.114 | D31: =SUM('4_win_BANK_CF'!O4:O61) -> 13450.114 | E31: =D31-C31 -> 3.2741809e-11 | F31: 20261027T142424323930Z | G31: a20e9350fde7107de910716bff2ea92303880a0996b67577bb0d060b03aefb7c
A32: 5_dat_BASE | B32: llcr_contractual_maturity | C32: 1.8637219 | D32: =SUM('5_dat_BASE_Inputs'!N12:N51)/'5_dat_BASE_Inputs'!K12 -> 1.8637219 | E32: =D32-C32 -> -8.8817842e-16 | F32: 20261027T142424948346Z | G32: e4020f4a51c751f9737f693e43863fb4e61d04a8e6c63bc11311d4c620b47b47
A33: 5_dat_BASE | B33: llcr_actual_repayment | C33: 1.3478329 | D33: =SUM('5_dat_BASE_Inputs'!O12:O51)/'5_dat_BASE_Inputs'!K12 -> 1.3478329 | E33: =D33-C33 -> -6.6613381e-16 | F33: 20261027T142424948346Z | G33: e4020f4a51c751f9737f693e43863fb4e61d04a8e6c63bc11311d4c620b47b47
A34: 5_dat_BASE | B34: plcr | C34: 2.7367108 | D34: =SUM('5_dat_BASE_Inputs'!P12:P51)/'5_dat_BASE_Inputs'!K12 -> 2.7367108 | E34: =D34-C34 -> -1.3322676e-15 | F34: 20261027T142424948346Z | G34: e4020f4a51c751f9737f693e43863fb4e61d04a8e6c63bc11311d4c620b47b47
A35: 5_dat_BASE | B35: min_rolling_llcr | C35: 1.3343809 | D35: =MIN('5_dat_BASE_Roll'!E2:E18) -> 1.3343809 | E35: =D35-C35 -> -2.220446e-16 | F35: 20261027T142424948346Z | G35: e4020f4a51c751f9737f693e43863fb4e61d04a8e6c63bc11311d4c620b47b47
A36: 5_dat_BASE | B36: project_npv_keur | C36: -82744.434 | D36: =SUM('5_dat_BASE_CF'!G4:G47) -> -82744.434 | E36: =D36-C36 -> 1.1641532e-10 | F36: 20261027T142424948346Z | G36: e4020f4a51c751f9737f693e43863fb4e61d04a8e6c63bc11311d4c620b47b47
A37: 5_dat_BASE | B37: sponsor_npv_keur | C37: -103927.19 | D37: =SUM('5_dat_BASE_CF'!O4:O47) -> -103927.19 | E37: =D37-C37 -> 8.7311491e-11 | F37: 20261027T142424948346Z | G37: e4020f4a51c751f9737f693e43863fb4e61d04a8e6c63bc11311d4c620b47b47
A38: 6_dat_BANK | B38: llcr_contractual_maturity | C38: 1.8637219 | D38: =SUM('6_dat_BANK_Inputs'!N12:N51)/'6_dat_BANK_Inputs'!K12 -> 1.8637219 | E38: =D38-C38 -> -8.8817842e-16 | F38: 20261027T142425566517Z | G38: b1037404532fc78adaba9208abffbf1077bbf0fec11395b843d4ba3e5ad5a751
A39: 6_dat_BANK | B39: llcr_actual_repayment | C39: 1.3478329 | D39: =SUM('6_dat_BANK_Inputs'!O12:O51)/'6_dat_BANK_Inputs'!K12 -> 1.3478329 | E39: =D39-C39 -> -6.6613381e-16 | F39: 20261027T142425566517Z | G39: b1037404532fc78adaba9208abffbf1077bbf0fec11395b843d4ba3e5ad5a751
A40: 6_dat_BANK | B40: plcr | C40: 2.7367108 | D40: =SUM('6_dat_BANK_Inputs'!P12:P51)/'6_dat_BANK_Inputs'!K12 -> 2.7367108 | E40: =D40-C40 -> -1.3322676e-15 | F40: 20261027T142425566517Z | G40: b1037404532fc78adaba9208abffbf1077bbf0fec11395b843d4ba3e5ad5a751
A41: 6_dat_BANK | B41: min_rolling_llcr | C41: 1.3343809 | D41: =MIN('6_dat_BANK_Roll'!E2:E18) -> 1.3343809 | E41: =D41-C41 -> -2.220446e-16 | F41: 20261027T142425566517Z | G41: b1037404532fc78adaba9208abffbf1077bbf0fec11395b843d4ba3e5ad5a751
...

Sheet 1_sol_BASE_Inputs
A1: Immutable Run | B1: 20261027T142419665354Z | C1: f29bf6421e872ac29a71c948d8472f5fcab1ba27f39b5a1268e00340be30b158
A2: Coverage rate (annual ratio) | B2: 0.055
A3: Observation date | B3: 47908
A4: Contractual maturity | B4: 53327
A5: Actual extinguishment | B5: 52047
A6: Project life end | B6: 56979
A8: BANK input authority: canonical debt-sizing CFADS; never relabelled P50
A11: End date | B11: Start date | C11: Index | D11: Engine BASE | E11: Engine BANK | F11: Statement EBITDA | G11: Statement FI | H11: Statement cash tax | I11: Rebuilt BASE | J11: BASE difference | K11: Senior opening | L11: Selected CFADS | M11: Discount divisor | N11: Contractual PV | O11: Actual PV | P11: Project-life PV
A12: 48029 | B12: 47908 | C12: 3 | D12: 1445.4426 | E12: 1288.197 | F12: 1445.4426 | G12: 0 | H12: 0 | I12: =F12+G12-H12 -> 1445.4426 | J12: =I12-D12 -> 0 | K12: 26925.862 | L12: =I12 -> 1445.4426 | M12: =(1+$B$2)^((A12-$B$3)/365) -> 1.0179076 | N12: =IF(A12<=$B$4,L12/M12,0) -> 1420.0136 | O12: =IF(A12<=$B$5,L12/M12,0) -> 1420.0136 | P12: =IF(A12<=$B$6,L12/M12,0) -> 1420.0136
A13: 48213 | B13: 48029 | C13: 4 | D13: 2092.4891 | E13: 1942.8545 | F13: 2180.0118 | G13: 0 | H13: 87.522783 | I13: =F13+G13-H13 -> 2092.4891 | J13: =I13-D13 -> 0 | K13: 26350.119 | L13: =I13 -> 2092.4891 | M13: =(1+$B$2)^((A13-$B$3)/365) -> 1.0457555 | N13: =IF(A13<=$B$4,L13/M13,0) -> 2000.9354 | O13: =IF(A13<=$B$5,L13/M13,0) -> 2000.9354 | P13: =IF(A13<=$B$6,L13/M13,0) -> 2000.9354
A14: 48395 | B14: 48213 | C14: 5 | D14: 2183.8883 | E14: 1946.2253 | F14: 2183.8883 | G14: 0 | H14: 0 | I14: =F14+G14-H14 -> 2183.8883 | J14: =I14-D14 -> 0 | K14: 25471.804 | L14: =I14 -> 2183.8883 | M14: =(1+$B$2)^((A14-$B$3)/365) -> 1.07405 | N14: =IF(A14<=$B$4,L14/M14,0) -> 2033.3208 | O14: =IF(A14<=$B$5,L14/M14,0) -> 2033.3208 | P14: =IF(A14<=$B$6,L14/M14,0) -> 2033.3208
A15: 48579 | B15: 48395 | C15: 6 | D15: 2067.315 | E15: 1957.9353 | F15: 2207.887 | G15: 0 | H15: 140.57203 | I15: =F15+G15-H15 -> 2067.315 | J15: =I15-D15 -> 0 | K15: 24558.208 | L15: =I15 -> 2067.315 | M15: =(1+$B$2)^((A15-$B$3)/365) -> 1.1034338 | N15: =IF(A15<=$B$4,L15/M15,0) -> 1873.5287 | O15: =IF(A15<=$B$5,L15/M15,0) -> 1873.5287 | P15: =IF(A15<=$B$6,L15/M15,0) -> 1873.5287
A16: 48760 | B16: 48579 | C16: 7 | D16: 2211.7263 | E16: 1970.9485 | F16: 2211.7263 | G16: 0 | H16: 0 | I16: =F16+G16-H16 -> 2211.7263 | J16: =I16-D16 -> 0 | K16: 23616.953 | L16: =I16 -> 2211.7263 | M16: =(1+$B$2)^((A16-$B$3)/365) -> 1.1331228 | N16: =IF(A16<=$B$4,L16/M16,0) -> 1951.8858 | O16: =IF(A16<=$B$5,L16/M16,0) -> 1951.8858 | P16: =IF(A16<=$B$6,L16/M16,0) -> 1951.8858
A17: 48944 | B17: 48760 | C17: 8 | D17: 2063.3634 | E17: 1939.9867 | F17: 2248.3847 | G17: 0 | H17: 185.02131 | I17: =F17+G17-H17 -> 2063.3634 | J17: =I17-D17 -> 0 | K17: 22627.571 | L17: =I17 -> 2063.3634 | M17: =(1+$B$2)^((A17-$B$3)/365) -> 1.1641227 | N17: =IF(A17<=$B$4,L17/M17,0) -> 1772.4621 | O17: =IF(A17<=$B$5,L17/M17,0) -> 1772.4621 | P17: =IF(A17<=$B$6,L17/M17,0) -> 1772.4621
A18: 49125 | B18: 48944 | C18: 9 | D18: 2246.1371 | E18: 2001.5261 | F18: 2246.1371 | G18: 0 | H18: 0 | I18: =F18+G18-H18 -> 2246.1371 | J18: =I18-D18 -> 0 | K18: 21647.001 | L18: =I18 -> 2246.1371 | M18: =(1+$B$2)^((A18-$B$3)/365) -> 1.1954445 | N18: =IF(A18<=$B$4,L18/M18,0) -> 1878.9136 | O18: =IF(A18<=$B$5,L18/M18,0) -> 1878.9136 | P18: =IF(A18<=$B$6,L18/M18,0) -> 1878.9136
A19: 49309 | B19: 49125 | C19: 10 | D19: 2052.966 | E19: 1927.6252 | F19: 2283.3658 | G19: 0 | H19: 230.39985 | I19: =F19+G19-H19 -> 2052.966 | J19: =I19-D19 -> 0 | K19: 20577.663 | L19: =I19 -> 2052.966 | M19: =(1+$B$2)^((A19-$B$3)/365) -> 1.2281495 | N19: =IF(A19<=$B$4,L19/M19,0) -> 1671.593 | O19: =IF(A19<=$B$5,L19/M19,0) -> 1671.593 | P19: =IF(A19<=$B$6,L19/M19,0) -> 1671.593
A20: 49490 | B20: 49309 | C20: 11 | D20: 2281.0797 | E20: 2032.5745 | F20: 2281.0797 | G20: 0 | H20: 0 | I20: =F20+G20-H20 -> 2281.0797 | J20: =I20-D20 -> 0 | K20: 19549.769 | L20: =I20 -> 2281.0797 | M20: =(1+$B$2)^((A20-$B$3)/365) -> 1.261194 | N20: =IF(A20<=$B$4,L20/M20,0) -> 1808.6668 | O20: =IF(A20<=$B$5,L20/M20,0) -> 1808.6668 | P20: =IF(A20<=$B$6,L20/M20,0) -> 1808.6668
A21: 49674 | B21: 49490 | C21: 12 | D21: 2040.6333 | E21: 1913.2961 | F21: 2318.8876 | G21: 0 | H21: 278.25428 | I21: =F21+G21-H21 -> 2040.6333 | J21: =I21-D21 -> 0 | K21: 18396.562 | L21: =I21 -> 2040.6333 | M21: =(1+$B$2)^((A21-$B$3)/365) -> 1.2956977 | N21: =IF(A21<=$B$4,L21/M21,0) -> 1574.9301 | O21: =IF(A21<=$B$5,L21/M21,0) -> 1574.9301 | P21: =IF(A21<=$B$6,L21/M21,0) -> 1574.9301
A22: 49856 | B22: 49674 | C22: 13 | D22: 2322.9966 | E22: 2069.834 | F22: 2322.9966 | G22: 0 | H22: 0 | I22: =F22+G22-H22 -> 2322.9966 | J22: =I22-D22 -> 0 | K22: 17319.297 | L22: =I22 -> 2322.9966 | M22: =(1+$B$2)^((A22-$B$3)/365) -> 1.3307549 | N22: =IF(A22<=$B$4,L22/M22,0) -> 1745.6232 | O22: =IF(A22<=$B$5,L22/M22,0) -> 1745.6232 | P22: =IF(A22<=$B$6,L22/M22,0) -> 1745.6232
A23: 50040 | B23: 49856 | C23: 14 | D23: 1871.7139 | E23: 1743.0526 | F23: 2348.524 | G23: 0 | H23: 476.81007 | I23: =F23+G23-H23 -> 1871.7139 | J23: =I23-D23 -> 0 | K23: 16076.008 | L23: =I23 -> 1871.7139 | M23: =(1+$B$2)^((A23-$B$3)/365) -> 1.3671616 | N23: =IF(A23<=$B$4,L23/M23,0) -> 1369.051 | O23: =IF(A23<=$B$5,L23/M23,0) -> 1369.051 | P23: =IF(A23<=$B$6,L23/M23,0) -> 1369.051
... A41: 53327 | B41: 53143 | C41: 32 | D41: 2114.0734 | E41: 1935.7096 | F41: 3285.8215 | G41: 0 | H41: 1171.748 | I41: =F41+G41-H41 -> 2114.0734 | J41: =I41-D41 -> 0 | K41: 0 | L41: =I41 -> 2114.0734 | M41: =(1+$B$2)^((A41-$B$3)/365) -> 2.214213 | N41: =IF(A41<=$B$4,L41/M41,0) -> 954.7742 | O41: =IF(A41<=$B$5,L41/M41,0) -> 0 | P41: =IF(A41<=$B$6,L41/M41,0) -> 954.7742
A42: 53508 | B42: 53327 | C42: 33 | D42: 3282.6912 | E42: 2929.0608 | F42: 3282.6912 | G42: 0 | H42: 0 | I42: =F42+G42-H42 -> 3282.6912 | J42: =I42-D42 -> 0 | L42: =I42 -> 3282.6912 | M42: =(1+$B$2)^((A42-$B$3)/365) -> 2.2737885 | N42: =IF(A42<=$B$4,L42/M42,0) -> 0 | O42: =IF(A42<=$B$5,L42/M42,0) -> 0 | P42: =IF(A42<=$B$6,L42/M42,0) -> 1443.71
A43: 53692 | B43: 53508 | C43: 34 | D43: 2109.9492 | E43: 1928.7458 | F43: 3337.1005 | G43: 0 | H43: 1227.1513 | I43: =F43+G43-H43 -> 2109.9492 | J43: =I43-D43 -> 0 | L43: =I43 -> 2109.9492 | M43: =(1+$B$2)^((A43-$B$3)/365) -> 2.3359947 | N43: =IF(A43<=$B$4,L43/M43,0) -> 0 | O43: =IF(A43<=$B$5,L43/M43,0) -> 0 | P43: =IF(A43<=$B$6,L43/M43,0) -> 903.23373
A44: 53873 | B44: 53692 | C44: 35 | D44: 3333.9169 | E44: 2974.6567 | F44: 3333.9169 | G44: 0 | H44: 0 | I44: =F44+G44-H44 -> 3333.9169 | J44: =I44-D44 -> 0 | L44: =I44 -> 3333.9169 | M44: =(1+$B$2)^((A44-$B$3)/365) -> 2.3988469 | N44: =IF(A44<=$B$4,L44/M44,0) -> 0 | O44: =IF(A44<=$B$5,L44/M44,0) -> 0 | P44: =IF(A44<=$B$6,L44/M44,0) -> 1389.7998
A45: 54057 | B45: 53873 | C45: 36 | D45: 2037.155 | E45: 1853.0655 | F45: 3389.1752 | G45: 0 | H45: 1352.0202 | I45: =F45+G45-H45 -> 2037.155 | J45: =I45-D45 -> 0 | L45: =I45 -> 2037.155 | M45: =(1+$B$2)^((A45-$B$3)/365) -> 2.4644744 | N45: =IF(A45<=$B$4,L45/M45,0) -> 0 | O45: =IF(A45<=$B$5,L45/M45,0) -> 0 | P45: =IF(A45<=$B$6,L45/M45,0) -> 826.60831
A46: 54239 | B46: 54057 | C46: 37 | D46: 3395.342 | E46: 3029.3486 | F46: 3395.342 | G46: 0 | H46: 0 | I46: =F46+G46-H46 -> 3395.342 | J46: =I46-D46 -> 0 | L46: =I46 -> 3395.342 | M46: =(1+$B$2)^((A46-$B$3)/365) -> 2.5311547 | N46: =IF(A46<=$B$4,L46/M46,0) -> 0 | O46: =IF(A46<=$B$5,L46/M46,0) -> 0 | P46: =IF(A46<=$B$6,L46/M46,0) -> 1341.4202
A47: 54423 | B47: 54239 | C47: 38 | D47: 2013.9043 | E47: 1827.9006 | F47: 3432.6534 | G47: 0 | H47: 1418.7491 | I47: =F47+G47-H47 -> 2013.9043 | J47: =I47-D47 -> 0 | L47: =I47 -> 2013.9043 | M47: =(1+$B$2)^((A47-$B$3)/365) -> 2.6004019 | N47: =IF(A47<=$B$4,L47/M47,0) -> 0 | O47: =IF(A47<=$B$5,L47/M47,0) -> 0 | P47: =IF(A47<=$B$6,L47/M47,0) -> 774.45887
A48: 54604 | B48: 54423 | C48: 39 | D48: 3438.765 | E48: 3067.9749 | F48: 3438.765 | G48: 0 | H48: 0 | I48: =F48+G48-H48 -> 3438.765 | J48: =I48-D48 -> 0 | L48: =I48 -> 3438.765 | M48: =(1+$B$2)^((A48-$B$3)/365) -> 2.6703682 | N48: =IF(A48<=$B$4,L48/M48,0) -> 0 | O48: =IF(A48<=$B$5,L48/M48,0) -> 0 | P48: =IF(A48<=$B$6,L48/M48,0) -> 1287.7494
A49: 54788 | B49: 54604 | C49: 40 | D49: 2050.3888 | E49: 1860.3926 | F49: 3495.7612 | G49: 0 | H49: 1445.3723 | I49: =F49+G49-H49 -> 2050.3888 | J49: =I49-D49 -> 0 | L49: =I49 -> 2050.3888 | M49: =(1+$B$2)^((A49-$B$3)/365) -> 2.743424 | N49: =IF(A49<=$B$4,L49/M49,0) -> 0 | O49: =IF(A49<=$B$5,L49/M49,0) -> 0 | P49: =IF(A49<=$B$6,L49/M49,0) -> 747.38313
A50: 54969 | B50: 54788 | C50: 41 | D50: 3492.4121 | E50: 3115.719 | F50: 3492.4121 | G50: 0 | H50: 0 | I50: =F50+G50-H50 -> 3492.4121 | J50: =I50-D50 -> 0 | L50: =I50 -> 3492.4121 | M50: =(1+$B$2)^((A50-$B$3)/365) -> 2.8172385 | N50: =IF(A50<=$B$4,L50/M50,0) -> 0 | O50: =IF(A50<=$B$5,L50/M50,0) -> 0 | P50: =IF(A50<=$B$6,L50/M50,0) -> 1239.658
A51: 55153 | B51: 54969 | C51: 42 | D51: 2077.8781 | E51: 1884.8572 | F51: 3550.2974 | G51: 0 | H51: 1472.4193 | I51: =F51+G51-H51 -> 2077.8781 | J51: =I51-D51 -> 0 | L51: =I51 -> 2077.8781 | M51: =(1+$B$2)^((A51-$B$3)/365) -> 2.8943123 | N51: =IF(A51<=$B$4,L51/M51,0) -> 0 | O51: =IF(A51<=$B$5,L51/M51,0) -> 0 | P51: =IF(A51<=$B$6,L51/M51,0) -> 717.91771
A52: 55334 | B52: 55153 | C52: 43 | D52: 3546.8913 | E52: 3164.2012 | F52: 3546.8913 | G52: 0 | H52: 0 | I52: =F52+G52-H52 -> 3546.8913 | J52: =I52-D52 -> 0 | L52: =I52 -> 3546.8913 | M52: =(1+$B$2)^((A52-$B$3)/365) -> 2.9721866 | N52: =IF(A52<=$B$4,L52/M52,0) -> 0 | O52: =IF(A52<=$B$5,L52/M52,0) -> 0 | P52: =IF(A52<=$B$6,L52/M52,0) -> 1193.3609
A53: 55518 | B53: 55334 | C53: 44 | D53: 2105.8052 | E53: 1909.7099 | F53: 3605.6795 | G53: 0 | H53: 1499.8743 | I53: =F53+G53-H53 -> 2105.8052 | J53: =I53-D53 -> 0 | L53: =I53 -> 2105.8052 | M53: =(1+$B$2)^((A53-$B$3)/365) -> 3.0534995 | N53: =IF(A53<=$B$4,L53/M53,0) -> 0 | O53: =IF(A53<=$B$5,L53/M53,0) -> 0 | P53: =IF(A53<=$B$6,L53/M53,0) -> 689.63665
... A61: 56979 | B61: 56795 | C61: 52 | D61: 2226.356 | E61: 2016.9015 | F61: 3835.9304 | G61: 0 | H61: 1609.5744 | I61: =F61+G61-H61 -> 2226.356 | J61: =I61-D61 -> 0 | L61: =I61 -> 2226.356 | M61: =(1+$B$2)^((A61-$B$3)/365) -> 3.7833054 | N61: =IF(A61<=$B$4,L61/M61,0) -> 0 | O61: =IF(A61<=$B$5,L61/M61,0) -> 0 | P61: =IF(A61<=$B$6,L61/M61,0) -> 588.46849

Sheet 1_sol_BASE_CF
A1: Project discount | B1: 0.08 | C1: Sponsor hurdle | D1: 0.12
A3: Project date | B3: Investment | C3: Operating | D3: Tax | E3: Terminal | F3: Rebuilt net project CF | G3: Discounted project CF | H3: Sponsor date | I3: Equity cash out | J3: SHL cash out | K3: Equity distributions | L3: SHL interest | M3: SHL principal | N3: Rebuilt sponsor net CF | O3: Discounted sponsor CF
A4: 47664 | B4: 20000 | C4: 0 | D4: 0 | E4: 0 | F4: =-B4+C4-D4+E4 -> -20000 | G4: =F4/((1+$B$1)^((A4-$A$4)/365)) -> -20000 | H4: 47484 | I4: 500 | J4: 8475.2873 | K4: 0 | L4: 0 | M4: 0 | N4: =-I4-J4+K4+L4+M4 -> -8975.2873 | O4: =N4/((1+$D$1)^((H4-$H$4)/365)) -> -8975.2873
A5: 47848 | B5: 13000 | C5: 0 | D5: 0 | E5: 0 | F5: =-B5+C5-D5+E5 -> -13000 | G5: =F5/((1+$B$1)^((A5-$A$4)/365)) -> -12505.3 | H5: 47665 | I5: 0 | J5: 0 | K5: 0 | L5: 0 | M5: 0 | N5: =-I5-J5+K5+L5+M5 -> 0 | O5: =N5/((1+$D$1)^((H5-$H$4)/365)) -> 0
A6: 47907 | B6: 0 | C6: 0 | D6: 0 | E6: 0 | F6: =-B6+C6-D6+E6 -> 0 | G6: =F6/((1+$B$1)^((A6-$A$4)/365)) -> 0 | H6: 47849 | I6: 0 | J6: 0 | K6: 0 | L6: 0 | M6: 0 | N6: =-I6-J6+K6+L6+M6 -> 0 | O6: =N6/((1+$D$1)^((H6-$H$4)/365)) -> 0
A7: 48029 | B7: 0 | C7: 1445.4426 | D7: 0 | E7: 0 | F7: =-B7+C7-D7+E7 -> 1445.4426 | G7: =F7/((1+$B$1)^((A7-$A$4)/365)) -> 1338.3728 | H7: 48029 | I7: 0 | J7: 0 | K7: 145.31827 | L7: 226.62686 | M7: 0 | N7: =-I7-J7+K7+L7+M7 -> 371.94513 | O7: =N7/((1+$D$1)^((H7-$H$4)/365)) -> 314.04288
A8: 48213 | B8: 0 | C8: 2180.0118 | D8: 540.68638 | E8: 0 | F8: =-B8+C8-D8+E8 -> 1639.3255 | G8: =F8/((1+$B$1)^((A8-$A$4)/365)) -> 1460.1322 | H8: 48213 | I8: 0 | J8: 0 | K8: 131.64576 | L8: 341.79789 | M8: 0 | N8: =-I8-J8+K8+L8+M8 -> 473.44365 | O8: =N8/((1+$D$1)^((H8-$H$4)/365)) -> 377.54358
A9: 48395 | B9: 0 | C9: 2183.8883 | D9: 0 | E9: 0 | F9: =-B9+C9-D9+E9 -> 2183.8883 | G9: =F9/((1+$B$1)^((A9-$A$4)/365)) -> 1871.9375 | H9: 48395 | I9: 0 | J9: 0 | K9: 224.87485 | L9: 337.15897 | M9: 0 | N9: =-I9-J9+K9+L9+M9 -> 562.03382 | O9: =N9/((1+$D$1)^((H9-$H$4)/365)) -> 423.5646
A10: 48579 | B10: 0 | C10: 2207.887 | D10: 659.66224 | E10: 0 | F10: =-B10+C10-D10+E10 -> 1548.2248 | G10: =F10/((1+$B$1)^((A10-$A$4)/365)) -> 1276.5731 | H10: 48579 | I10: 0 | J10: 0 | K10: 94.838238 | L10: 340.86401 | M10: 0 | N10: =-I10-J10+K10+L10+M10 -> 435.70225 | O10: =N10/((1+$D$1)^((H10-$H$4)/365)) -> 310.12426
A11: 48760 | B11: 0 | C11: 2211.7263 | D11: 0 | E11: 0 | F11: =-B11+C11-D11+E11 -> 2211.7263 | G11: =F11/((1+$B$1)^((A11-$A$4)/365)) -> 1755.3695 | H11: 48760 | I11: 0 | J11: 0 | K11: 233.04408 | L11: 336.22509 | M11: 0 | N11: =-I11-J11+K11+L11+M11 -> 569.26917 | O11: =N11/((1+$D$1)^((H11-$H$4)/365)) -> 383.05122
A12: 48944 | B12: 0 | C12: 2248.3847 | D12: 676.74194 | E12: 0 | F12: =-B12+C12-D12+E12 -> 1571.6428 | G12: =F12/((1+$B$1)^((A12-$A$4)/365)) -> 1199.8909 | H12: 48944 | I12: 0 | J12: 0 | K12: 104.90991 | L12: 341.79789 | M12: 0 | N12: =-I12-J12+K12+L12+M12 -> 446.7078 | O12: =N12/((1+$D$1)^((H12-$H$4)/365)) -> 283.89088
A13: 49125 | B13: 0 | C13: 2246.1371 | D13: 0 | E13: 0 | F13: =-B13+C13-D13+E13 -> 2246.1371 | G13: =F13/((1+$B$1)^((A13-$A$4)/365)) -> 1650.6297 | H13: 49125 | I13: 0 | J13: 0 | K13: 241.97353 | L13: 336.22509 | M13: 0 | N13: =-I13-J13+K13+L13+M13 -> 578.19862 | O13: =N13/((1+$D$1)^((H13-$H$4)/365)) -> 347.37473
A14: 49309 | B14: 0 | C14: 2283.3658 | D14: 694.09066 | E14: 0 | F14: =-B14+C14-D14+E14 -> 1589.2752 | G14: =F14/((1+$B$1)^((A14-$A$4)/365)) -> 1123.4746 | H14: 49309 | I14: 0 | J14: 0 | K14: 104.81381 | L14: 341.79789 | M14: 0 | N14: =-I14-J14+K14+L14+M14 -> 446.61169 | O14: =N14/((1+$D$1)^((H14-$H$4)/365)) -> 253.41947
A15: 49490 | B15: 0 | C15: 2281.0797 | D15: 0 | E15: 0 | F15: =-B15+C15-D15+E15 -> 2281.0797 | G15: =F15/((1+$B$1)^((A15-$A$4)/365)) -> 1552.1372 | H15: 49490 | I15: 0 | J15: 0 | K15: 251.04247 | L15: 336.22509 | M15: 0 | N15: =-I15-J15+K15+L15+M15 -> 587.26756 | O15: =N15/((1+$D$1)^((H15-$H$4)/365)) -> 315.02075
... A56: 56979 | B56: 0 | C56: 3835.9304 | D56: 1609.5744 | E56: 0 | F56: =-B56+C56-D56+E56 -> 2226.356 | G56: =F56/((1+$B$1)^((A56-$A$4)/365)) -> 312.32163 | H56: 56979 | I56: 0 | J56: 0 | K56: 2226.356 | L56: 0 | M56: 0 | N56: =-I56-J56+K56+L56+M56 -> 2226.356 | O56: =N56/((1+$D$1)^((H56-$H$4)/365)) -> 116.74863

Sheet 1_sol_BASE_Roll
A1: Observation date | B1: Index | C1: Opening Senior | D1: Remaining horizon | E1: Independent LLCR | F1: Persisted ratio | G1: Difference
A2: 47908 | B2: 3 | C2: 26925.862 | D2: 25 | E2: =SUMPRODUCT(('1_sol_BASE_Inputs'!$C$12:$C$61>=B2)*('1_sol_BASE_Inputs'!$C$12:$C$61<=D2)*'1_sol_BASE_Inputs'!$L$12:$L$61/((1+'1_sol_BASE_Inputs'!$B$2)^(('1_sol_BASE_Inputs'!$A$12:$A$61-A2)/365)))/C2 -> 1.3558183 | F2: 1.3558183 | G2: =E2-F2 -> -6.6613381e-16
A3: 48029 | B3: 4 | C3: 26350.119 | D3: 25 | E3: =SUMPRODUCT(('1_sol_BASE_Inputs'!$C$12:$C$61>=B3)*('1_sol_BASE_Inputs'!$C$12:$C$61<=D3)*'1_sol_BASE_Inputs'!$L$12:$L$61/((1+'1_sol_BASE_Inputs'!$B$2)^(('1_sol_BASE_Inputs'!$A$12:$A$61-A3)/365)))/C3 -> 1.3553972 | F3: 1.3553972 | G3: =E3-F3 -> -6.6613381e-16
A4: 48213 | B4: 5 | C4: 25471.804 | D4: 25 | E4: =SUMPRODUCT(('1_sol_BASE_Inputs'!$C$12:$C$61>=B4)*('1_sol_BASE_Inputs'!$C$12:$C$61<=D4)*'1_sol_BASE_Inputs'!$L$12:$L$61/((1+'1_sol_BASE_Inputs'!$B$2)^(('1_sol_BASE_Inputs'!$A$12:$A$61-A4)/365)))/C4 -> 1.3583441 | F4: 1.3583441 | G4: =E4-F4 -> -2.220446e-16
A5: 48395 | B5: 6 | C5: 24558.208 | D5: 25 | E5: =SUMPRODUCT(('1_sol_BASE_Inputs'!$C$12:$C$61>=B5)*('1_sol_BASE_Inputs'!$C$12:$C$61<=D5)*'1_sol_BASE_Inputs'!$L$12:$L$61/((1+'1_sol_BASE_Inputs'!$B$2)^(('1_sol_BASE_Inputs'!$A$12:$A$61-A5)/365)))/C5 -> 1.3580686 | F5: 1.3580686 | G5: =E5-F5 -> -6.6613381e-16
A6: 48579 | B6: 7 | C6: 23616.953 | D6: 25 | E6: =SUMPRODUCT(('1_sol_BASE_Inputs'!$C$12:$C$61>=B6)*('1_sol_BASE_Inputs'!$C$12:$C$61<=D6)*'1_sol_BASE_Inputs'!$L$12:$L$61/((1+'1_sol_BASE_Inputs'!$B$2)^(('1_sol_BASE_Inputs'!$A$12:$A$61-A6)/365)))/C6 -> 1.363294 | F6: 1.363294 | G6: =E6-F6 -> -2.220446e-16
A7: 48760 | B7: 8 | C7: 22627.571 | D7: 25 | E7: =SUMPRODUCT(('1_sol_BASE_Inputs'!$C$12:$C$61>=B7)*('1_sol_BASE_Inputs'!$C$12:$C$61<=D7)*'1_sol_BASE_Inputs'!$L$12:$L$61/((1+'1_sol_BASE_Inputs'!$B$2)^(('1_sol_BASE_Inputs'!$A$12:$A$61-A7)/365)))/C7 -> 1.3634434 | F7: 1.3634434 | G7: =E7-F7 -> -4.4408921e-16
A8: 48944 | B8: 9 | C8: 21647.001 | D8: 25 | E8: =SUMPRODUCT(('1_sol_BASE_Inputs'!$C$12:$C$61>=B8)*('1_sol_BASE_Inputs'!$C$12:$C$61<=D8)*'1_sol_BASE_Inputs'!$L$12:$L$61/((1+'1_sol_BASE_Inputs'!$B$2)^(('1_sol_BASE_Inputs'!$A$12:$A$61-A8)/365)))/C8 -> 1.3688769 | F8: 1.3688769 | G8: =E8-F8 -> -2.220446e-16
A9: 49125 | B9: 10 | C9: 20577.663 | D9: 25 | E9: =SUMPRODUCT(('1_sol_BASE_Inputs'!$C$12:$C$61>=B9)*('1_sol_BASE_Inputs'!$C$12:$C$61<=D9)*'1_sol_BASE_Inputs'!$L$12:$L$61/((1+'1_sol_BASE_Inputs'!$B$2)^(('1_sol_BASE_Inputs'!$A$12:$A$61-A9)/365)))/C9 -> 1.3696027 | F9: 1.3696027 | G9: =E9-F9 -> -8.8817842e-16
A10: 49309 | B10: 11 | C10: 19549.769 | D10: 25 | E10: =SUMPRODUCT(('1_sol_BASE_Inputs'!$C$12:$C$61>=B10)*('1_sol_BASE_Inputs'!$C$12:$C$61<=D10)*'1_sol_BASE_Inputs'!$L$12:$L$61/((1+'1_sol_BASE_Inputs'!$B$2)^(('1_sol_BASE_Inputs'!$A$12:$A$61-A10)/365)))/C10 -> 1.3760413 | F10: 1.3760413 | G10: =E10-F10 -> -2.220446e-16
A11: 49490 | B11: 12 | C11: 18396.562 | D11: 25 | E11: =SUMPRODUCT(('1_sol_BASE_Inputs'!$C$12:$C$61>=B11)*('1_sol_BASE_Inputs'!$C$12:$C$61<=D11)*'1_sol_BASE_Inputs'!$L$12:$L$61/((1+'1_sol_BASE_Inputs'!$B$2)^(('1_sol_BASE_Inputs'!$A$12:$A$61-A11)/365)))/C11 -> 1.3776495 | F11: 1.3776495 | G11: =E11-F11 -> -4.4408921e-16
A12: 49674 | B12: 13 | C12: 17319.297 | D12: 25 | E12: =SUMPRODUCT(('1_sol_BASE_Inputs'!$C$12:$C$61>=B12)*('1_sol_BASE_Inputs'!$C$12:$C$61<=D12)*'1_sol_BASE_Inputs'!$L$12:$L$61/((1+'1_sol_BASE_Inputs'!$B$2)^(('1_sol_BASE_Inputs'!$A$12:$A$61-A12)/365)))/C12 -> 1.3855495 | F12: 1.3855495 | G12: =E12-F12 -> -4.4408921e-16
A13: 49856 | B13: 14 | C13: 16076.008 | D13: 25 | E13: =SUMPRODUCT(('1_sol_BASE_Inputs'!$C$12:$C$61>=B13)*('1_sol_BASE_Inputs'!$C$12:$C$61<=D13)*'1_sol_BASE_Inputs'!$L$12:$L$61/((1+'1_sol_BASE_Inputs'!$B$2)^(('1_sol_BASE_Inputs'!$A$12:$A$61-A13)/365)))/C13 -> 1.3885921 | F13: 1.3885921 | G13: =E13-F13 -> -4.4408921e-16
... A24: 51866 | B24: 25 | C24: 1274.9554 | D24: 25 | E24: =SUMPRODUCT(('1_sol_BASE_Inputs'!$C$12:$C$61>=B24)*('1_sol_BASE_Inputs'!$C$12:$C$61<=D24)*'1_sol_BASE_Inputs'!$L$12:$L$61/((1+'1_sol_BASE_Inputs'!$B$2)^(('1_sol_BASE_Inputs'!$A$12:$A$61-A24)/365)))/C24 -> 2.3566746 | F24: 2.3566746 | G24: =E24-F24 -> 0

Sheet 2_sol_BANK_Inputs
A1: Immutable Run | B1: 20261027T142420977782Z | C1: 9474dc7cb5d31f1a7675af01a064b9349d1a5a170245cf304f68cc6725daf89e
A2: Coverage rate (annual ratio) | B2: 0.055
A3: Observation date | B3: 47908
A4: Contractual maturity | B4: 53327
A5: Actual extinguishment | B5: 52047
A6: Project life end | B6: 56979
A8: BANK input authority: canonical debt-sizing CFADS; never relabelled P50
A11: End date | B11: Start date | C11: Index | D11: Engine BASE | E11: Engine BANK | F11: Statement EBITDA | G11: Statement FI | H11: Statement cash tax | I11: Rebuilt BASE | J11: BASE difference | K11: Senior opening | L11: Selected CFADS | M11: Discount divisor | N11: Contractual PV | O11: Actual PV | P11: Project-life PV
A12: 48029 | B12: 47908 | C12: 3 | D12: 1445.4426 | E12: 1288.197 | F12: 1445.4426 | G12: 0 | H12: 0 | I12: =F12+G12-H12 -> 1445.4426 | J12: =I12-D12 -> 0 | K12: 26925.862 | L12: =E12 -> 1288.197 | M12: =(1+$B$2)^((A12-$B$3)/365) -> 1.0179076 | N12: =IF(A12<=$B$4,L12/M12,0) -> 1265.5343 | O12: =IF(A12<=$B$5,L12/M12,0) -> 1265.5343 | P12: =IF(A12<=$B$6,L12/M12,0) -> 1265.5343
A13: 48213 | B13: 48029 | C13: 4 | D13: 2092.4891 | E13: 1942.8545 | F13: 2180.0118 | G13: 0 | H13: 87.522783 | I13: =F13+G13-H13 -> 2092.4891 | J13: =I13-D13 -> 0 | K13: 26350.119 | L13: =E13 -> 1942.8545 | M13: =(1+$B$2)^((A13-$B$3)/365) -> 1.0457555 | N13: =IF(A13<=$B$4,L13/M13,0) -> 1857.8478 | O13: =IF(A13<=$B$5,L13/M13,0) -> 1857.8478 | P13: =IF(A13<=$B$6,L13/M13,0) -> 1857.8478
A14: 48395 | B14: 48213 | C14: 5 | D14: 2183.8883 | E14: 1946.2253 | F14: 2183.8883 | G14: 0 | H14: 0 | I14: =F14+G14-H14 -> 2183.8883 | J14: =I14-D14 -> 0 | K14: 25471.804 | L14: =E14 -> 1946.2253 | M14: =(1+$B$2)^((A14-$B$3)/365) -> 1.07405 | N14: =IF(A14<=$B$4,L14/M14,0) -> 1812.0435 | O14: =IF(A14<=$B$5,L14/M14,0) -> 1812.0435 | P14: =IF(A14<=$B$6,L14/M14,0) -> 1812.0435
A15: 48579 | B15: 48395 | C15: 6 | D15: 2067.315 | E15: 1957.9353 | F15: 2207.887 | G15: 0 | H15: 140.57203 | I15: =F15+G15-H15 -> 2067.315 | J15: =I15-D15 -> 0 | K15: 24558.208 | L15: =E15 -> 1957.9353 | M15: =(1+$B$2)^((A15-$B$3)/365) -> 1.1034338 | N15: =IF(A15<=$B$4,L15/M15,0) -> 1774.4021 | O15: =IF(A15<=$B$5,L15/M15,0) -> 1774.4021 | P15: =IF(A15<=$B$6,L15/M15,0) -> 1774.4021
A16: 48760 | B16: 48579 | C16: 7 | D16: 2211.7263 | E16: 1970.9485 | F16: 2211.7263 | G16: 0 | H16: 0 | I16: =F16+G16-H16 -> 2211.7263 | J16: =I16-D16 -> 0 | K16: 23616.953 | L16: =E16 -> 1970.9485 | M16: =(1+$B$2)^((A16-$B$3)/365) -> 1.1331228 | N16: =IF(A16<=$B$4,L16/M16,0) -> 1739.3954 | O16: =IF(A16<=$B$5,L16/M16,0) -> 1739.3954 | P16: =IF(A16<=$B$6,L16/M16,0) -> 1739.3954
A17: 48944 | B17: 48760 | C17: 8 | D17: 2063.3634 | E17: 1939.9867 | F17: 2248.3847 | G17: 0 | H17: 185.02131 | I17: =F17+G17-H17 -> 2063.3634 | J17: =I17-D17 -> 0 | K17: 22627.571 | L17: =E17 -> 1939.9867 | M17: =(1+$B$2)^((A17-$B$3)/365) -> 1.1641227 | N17: =IF(A17<=$B$4,L17/M17,0) -> 1666.4796 | O17: =IF(A17<=$B$5,L17/M17,0) -> 1666.4796 | P17: =IF(A17<=$B$6,L17/M17,0) -> 1666.4796
A18: 49125 | B18: 48944 | C18: 9 | D18: 2246.1371 | E18: 2001.5261 | F18: 2246.1371 | G18: 0 | H18: 0 | I18: =F18+G18-H18 -> 2246.1371 | J18: =I18-D18 -> 0 | K18: 21647.001 | L18: =E18 -> 2001.5261 | M18: =(1+$B$2)^((A18-$B$3)/365) -> 1.1954445 | N18: =IF(A18<=$B$4,L18/M18,0) -> 1674.2944 | O18: =IF(A18<=$B$5,L18/M18,0) -> 1674.2944 | P18: =IF(A18<=$B$6,L18/M18,0) -> 1674.2944
A19: 49309 | B19: 49125 | C19: 10 | D19: 2052.966 | E19: 1927.6252 | F19: 2283.3658 | G19: 0 | H19: 230.39985 | I19: =F19+G19-H19 -> 2052.966 | J19: =I19-D19 -> 0 | K19: 20577.663 | L19: =E19 -> 1927.6252 | M19: =(1+$B$2)^((A19-$B$3)/365) -> 1.2281495 | N19: =IF(A19<=$B$4,L19/M19,0) -> 1569.5363 | O19: =IF(A19<=$B$5,L19/M19,0) -> 1569.5363 | P19: =IF(A19<=$B$6,L19/M19,0) -> 1569.5363
A20: 49490 | B20: 49309 | C20: 11 | D20: 2281.0797 | E20: 2032.5745 | F20: 2281.0797 | G20: 0 | H20: 0 | I20: =F20+G20-H20 -> 2281.0797 | J20: =I20-D20 -> 0 | K20: 19549.769 | L20: =E20 -> 2032.5745 | M20: =(1+$B$2)^((A20-$B$3)/365) -> 1.261194 | N20: =IF(A20<=$B$4,L20/M20,0) -> 1611.6272 | O20: =IF(A20<=$B$5,L20/M20,0) -> 1611.6272 | P20: =IF(A20<=$B$6,L20/M20,0) -> 1611.6272
A21: 49674 | B21: 49490 | C21: 12 | D21: 2040.6333 | E21: 1913.2961 | F21: 2318.8876 | G21: 0 | H21: 278.25428 | I21: =F21+G21-H21 -> 2040.6333 | J21: =I21-D21 -> 0 | K21: 18396.562 | L21: =E21 -> 1913.2961 | M21: =(1+$B$2)^((A21-$B$3)/365) -> 1.2956977 | N21: =IF(A21<=$B$4,L21/M21,0) -> 1476.6532 | O21: =IF(A21<=$B$5,L21/M21,0) -> 1476.6532 | P21: =IF(A21<=$B$6,L21/M21,0) -> 1476.6532
A22: 49856 | B22: 49674 | C22: 13 | D22: 2322.9966 | E22: 2069.834 | F22: 2322.9966 | G22: 0 | H22: 0 | I22: =F22+G22-H22 -> 2322.9966 | J22: =I22-D22 -> 0 | K22: 17319.297 | L22: =E22 -> 2069.834 | M22: =(1+$B$2)^((A22-$B$3)/365) -> 1.3307549 | N22: =IF(A22<=$B$4,L22/M22,0) -> 1555.3834 | O22: =IF(A22<=$B$5,L22/M22,0) -> 1555.3834 | P22: =IF(A22<=$B$6,L22/M22,0) -> 1555.3834
A23: 50040 | B23: 49856 | C23: 14 | D23: 1871.7139 | E23: 1743.0526 | F23: 2348.524 | G23: 0 | H23: 476.81007 | I23: =F23+G23-H23 -> 1871.7139 | J23: =I23-D23 -> 0 | K23: 16076.008 | L23: =E23 -> 1743.0526 | M23: =(1+$B$2)^((A23-$B$3)/365) -> 1.3671616 | N23: =IF(A23<=$B$4,L23/M23,0) -> 1274.9427 | O23: =IF(A23<=$B$5,L23/M23,0) -> 1274.9427 | P23: =IF(A23<=$B$6,L23/M23,0) -> 1274.9427
... A41: 53327 | B41: 53143 | C41: 32 | D41: 2114.0734 | E41: 1935.7096 | F41: 3285.8215 | G41: 0 | H41: 1171.748 | I41: =F41+G41-H41 -> 2114.0734 | J41: =I41-D41 -> 0 | K41: 0 | L41: =E41 -> 1935.7096 | M41: =(1+$B$2)^((A41-$B$3)/365) -> 2.214213 | N41: =IF(A41<=$B$4,L41/M41,0) -> 874.22014 | O41: =IF(A41<=$B$5,L41/M41,0) -> 0 | P41: =IF(A41<=$B$6,L41/M41,0) -> 874.22014
A42: 53508 | B42: 53327 | C42: 33 | D42: 3282.6912 | E42: 2929.0608 | F42: 3282.6912 | G42: 0 | H42: 0 | I42: =F42+G42-H42 -> 3282.6912 | J42: =I42-D42 -> 0 | L42: =E42 -> 2929.0608 | M42: =(1+$B$2)^((A42-$B$3)/365) -> 2.2737885 | N42: =IF(A42<=$B$4,L42/M42,0) -> 0 | O42: =IF(A42<=$B$5,L42/M42,0) -> 0 | P42: =IF(A42<=$B$6,L42/M42,0) -> 1288.1852
A43: 53692 | B43: 53508 | C43: 34 | D43: 2109.9492 | E43: 1928.7458 | F43: 3337.1005 | G43: 0 | H43: 1227.1513 | I43: =F43+G43-H43 -> 2109.9492 | J43: =I43-D43 -> 0 | L43: =E43 -> 1928.7458 | M43: =(1+$B$2)^((A43-$B$3)/365) -> 2.3359947 | N43: =IF(A43<=$B$4,L43/M43,0) -> 0 | O43: =IF(A43<=$B$5,L43/M43,0) -> 0 | P43: =IF(A43<=$B$6,L43/M43,0) -> 825.6636
A44: 53873 | B44: 53692 | C44: 35 | D44: 3333.9169 | E44: 2974.6567 | F44: 3333.9169 | G44: 0 | H44: 0 | I44: =F44+G44-H44 -> 3333.9169 | J44: =I44-D44 -> 0 | L44: =E44 -> 2974.6567 | M44: =(1+$B$2)^((A44-$B$3)/365) -> 2.3988469 | N44: =IF(A44<=$B$4,L44/M44,0) -> 0 | O44: =IF(A44<=$B$5,L44/M44,0) -> 0 | P44: =IF(A44<=$B$6,L44/M44,0) -> 1240.0361
A45: 54057 | B45: 53873 | C45: 36 | D45: 2037.155 | E45: 1853.0655 | F45: 3389.1752 | G45: 0 | H45: 1352.0202 | I45: =F45+G45-H45 -> 2037.155 | J45: =I45-D45 -> 0 | L45: =E45 -> 1853.0655 | M45: =(1+$B$2)^((A45-$B$3)/365) -> 2.4644744 | N45: =IF(A45<=$B$4,L45/M45,0) -> 0 | O45: =IF(A45<=$B$5,L45/M45,0) -> 0 | P45: =IF(A45<=$B$6,L45/M45,0) -> 751.91103
A46: 54239 | B46: 54057 | C46: 37 | D46: 3395.342 | E46: 3029.3486 | F46: 3395.342 | G46: 0 | H46: 0 | I46: =F46+G46-H46 -> 3395.342 | J46: =I46-D46 -> 0 | L46: =E46 -> 3029.3486 | M46: =(1+$B$2)^((A46-$B$3)/365) -> 2.5311547 | N46: =IF(A46<=$B$4,L46/M46,0) -> 0 | O46: =IF(A46<=$B$5,L46/M46,0) -> 0 | P46: =IF(A46<=$B$6,L46/M46,0) -> 1196.8247
A47: 54423 | B47: 54239 | C47: 38 | D47: 2013.9043 | E47: 1827.9006 | F47: 3432.6534 | G47: 0 | H47: 1418.7491 | I47: =F47+G47-H47 -> 2013.9043 | J47: =I47-D47 -> 0 | L47: =E47 -> 1827.9006 | M47: =(1+$B$2)^((A47-$B$3)/365) -> 2.6004019 | N47: =IF(A47<=$B$4,L47/M47,0) -> 0 | O47: =IF(A47<=$B$5,L47/M47,0) -> 0 | P47: =IF(A47<=$B$6,L47/M47,0) -> 702.93003
A48: 54604 | B48: 54423 | C48: 39 | D48: 3438.765 | E48: 3067.9749 | F48: 3438.765 | G48: 0 | H48: 0 | I48: =F48+G48-H48 -> 3438.765 | J48: =I48-D48 -> 0 | L48: =E48 -> 3067.9749 | M48: =(1+$B$2)^((A48-$B$3)/365) -> 2.6703682 | N48: =IF(A48<=$B$4,L48/M48,0) -> 0 | O48: =IF(A48<=$B$5,L48/M48,0) -> 0 | P48: =IF(A48<=$B$6,L48/M48,0) -> 1148.8958
A49: 54788 | B49: 54604 | C49: 40 | D49: 2050.3888 | E49: 1860.3926 | F49: 3495.7612 | G49: 0 | H49: 1445.3723 | I49: =F49+G49-H49 -> 2050.3888 | J49: =I49-D49 -> 0 | L49: =E49 -> 1860.3926 | M49: =(1+$B$2)^((A49-$B$3)/365) -> 2.743424 | N49: =IF(A49<=$B$4,L49/M49,0) -> 0 | O49: =IF(A49<=$B$5,L49/M49,0) -> 0 | P49: =IF(A49<=$B$6,L49/M49,0) -> 678.128
A50: 54969 | B50: 54788 | C50: 41 | D50: 3492.4121 | E50: 3115.719 | F50: 3492.4121 | G50: 0 | H50: 0 | I50: =F50+G50-H50 -> 3492.4121 | J50: =I50-D50 -> 0 | L50: =E50 -> 3115.719 | M50: =(1+$B$2)^((A50-$B$3)/365) -> 2.8172385 | N50: =IF(A50<=$B$4,L50/M50,0) -> 0 | O50: =IF(A50<=$B$5,L50/M50,0) -> 0 | P50: =IF(A50<=$B$6,L50/M50,0) -> 1105.9479
A51: 55153 | B51: 54969 | C51: 42 | D51: 2077.8781 | E51: 1884.8572 | F51: 3550.2974 | G51: 0 | H51: 1472.4193 | I51: =F51+G51-H51 -> 2077.8781 | J51: =I51-D51 -> 0 | L51: =E51 -> 1884.8572 | M51: =(1+$B$2)^((A51-$B$3)/365) -> 2.8943123 | N51: =IF(A51<=$B$4,L51/M51,0) -> 0 | O51: =IF(A51<=$B$5,L51/M51,0) -> 0 | P51: =IF(A51<=$B$6,L51/M51,0) -> 651.22798
A52: 55334 | B52: 55153 | C52: 43 | D52: 3546.8913 | E52: 3164.2012 | F52: 3546.8913 | G52: 0 | H52: 0 | I52: =F52+G52-H52 -> 3546.8913 | J52: =I52-D52 -> 0 | L52: =E52 -> 3164.2012 | M52: =(1+$B$2)^((A52-$B$3)/365) -> 2.9721866 | N52: =IF(A52<=$B$4,L52/M52,0) -> 0 | O52: =IF(A52<=$B$5,L52/M52,0) -> 0 | P52: =IF(A52<=$B$6,L52/M52,0) -> 1064.6038
A53: 55518 | B53: 55334 | C53: 44 | D53: 2105.8052 | E53: 1909.7099 | F53: 3605.6795 | G53: 0 | H53: 1499.8743 | I53: =F53+G53-H53 -> 2105.8052 | J53: =I53-D53 -> 0 | L53: =E53 -> 1909.7099 | M53: =(1+$B$2)^((A53-$B$3)/365) -> 3.0534995 | N53: =IF(A53<=$B$4,L53/M53,0) -> 0 | O53: =IF(A53<=$B$5,L53/M53,0) -> 0 | P53: =IF(A53<=$B$6,L53/M53,0) -> 625.4168
... A61: 56979 | B61: 56795 | C61: 52 | D61: 2226.356 | E61: 2016.9015 | F61: 3835.9304 | G61: 0 | H61: 1609.5744 | I61: =F61+G61-H61 -> 2226.356 | J61: =I61-D61 -> 0 | L61: =E61 -> 2016.9015 | M61: =(1+$B$2)^((A61-$B$3)/365) -> 3.7833054 | N61: =IF(A61<=$B$4,L61/M61,0) -> 0 | O61: =IF(A61<=$B$5,L61/M61,0) -> 0 | P61: =IF(A61<=$B$6,L61/M61,0) -> 533.10567

Sheet 2_sol_BANK_CF
A1: Project discount | B1: 0.08 | C1: Sponsor hurdle | D1: 0.12
A3: Project date | B3: Investment | C3: Operating | D3: Tax | E3: Terminal | F3: Rebuilt net project CF | G3: Discounted project CF | H3: Sponsor date | I3: Equity cash out | J3: SHL cash out | K3: Equity distributions | L3: SHL interest | M3: SHL principal | N3: Rebuilt sponsor net CF | O3: Discounted sponsor CF
A4: 47664 | B4: 20000 | C4: 0 | D4: 0 | E4: 0 | F4: =-B4+C4-D4+E4 -> -20000 | G4: =F4/((1+$B$1)^((A4-$A$4)/365)) -> -20000 | H4: 47484 | I4: 500 | J4: 8475.2873 | K4: 0 | L4: 0 | M4: 0 | N4: =-I4-J4+K4+L4+M4 -> -8975.2873 | O4: =N4/((1+$D$1)^((H4-$H$4)/365)) -> -8975.2873
A5: 47848 | B5: 13000 | C5: 0 | D5: 0 | E5: 0 | F5: =-B5+C5-D5+E5 -> -13000 | G5: =F5/((1+$B$1)^((A5-$A$4)/365)) -> -12505.3 | H5: 47665 | I5: 0 | J5: 0 | K5: 0 | L5: 0 | M5: 0 | N5: =-I5-J5+K5+L5+M5 -> 0 | O5: =N5/((1+$D$1)^((H5-$H$4)/365)) -> 0
A6: 47907 | B6: 0 | C6: 0 | D6: 0 | E6: 0 | F6: =-B6+C6-D6+E6 -> 0 | G6: =F6/((1+$B$1)^((A6-$A$4)/365)) -> 0 | H6: 47849 | I6: 0 | J6: 0 | K6: 0 | L6: 0 | M6: 0 | N6: =-I6-J6+K6+L6+M6 -> 0 | O6: =N6/((1+$D$1)^((H6-$H$4)/365)) -> 0
A7: 48029 | B7: 0 | C7: 1445.4426 | D7: 0 | E7: 0 | F7: =-B7+C7-D7+E7 -> 1445.4426 | G7: =F7/((1+$B$1)^((A7-$A$4)/365)) -> 1338.3728 | H7: 48029 | I7: 0 | J7: 0 | K7: 145.31827 | L7: 226.62686 | M7: 0 | N7: =-I7-J7+K7+L7+M7 -> 371.94513 | O7: =N7/((1+$D$1)^((H7-$H$4)/365)) -> 314.04288
A8: 48213 | B8: 0 | C8: 2180.0118 | D8: 540.68638 | E8: 0 | F8: =-B8+C8-D8+E8 -> 1639.3255 | G8: =F8/((1+$B$1)^((A8-$A$4)/365)) -> 1460.1322 | H8: 48213 | I8: 0 | J8: 0 | K8: 131.64576 | L8: 341.79789 | M8: 0 | N8: =-I8-J8+K8+L8+M8 -> 473.44365 | O8: =N8/((1+$D$1)^((H8-$H$4)/365)) -> 377.54358
A9: 48395 | B9: 0 | C9: 2183.8883 | D9: 0 | E9: 0 | F9: =-B9+C9-D9+E9 -> 2183.8883 | G9: =F9/((1+$B$1)^((A9-$A$4)/365)) -> 1871.9375 | H9: 48395 | I9: 0 | J9: 0 | K9: 224.87485 | L9: 337.15897 | M9: 0 | N9: =-I9-J9+K9+L9+M9 -> 562.03382 | O9: =N9/((1+$D$1)^((H9-$H$4)/365)) -> 423.5646
A10: 48579 | B10: 0 | C10: 2207.887 | D10: 659.66224 | E10: 0 | F10: =-B10+C10-D10+E10 -> 1548.2248 | G10: =F10/((1+$B$1)^((A10-$A$4)/365)) -> 1276.5731 | H10: 48579 | I10: 0 | J10: 0 | K10: 94.838238 | L10: 340.86401 | M10: 0 | N10: =-I10-J10+K10+L10+M10 -> 435.70225 | O10: =N10/((1+$D$1)^((H10-$H$4)/365)) -> 310.12426
A11: 48760 | B11: 0 | C11: 2211.7263 | D11: 0 | E11: 0 | F11: =-B11+C11-D11+E11 -> 2211.7263 | G11: =F11/((1+$B$1)^((A11-$A$4)/365)) -> 1755.3695 | H11: 48760 | I11: 0 | J11: 0 | K11: 233.04408 | L11: 336.22509 | M11: 0 | N11: =-I11-J11+K11+L11+M11 -> 569.26917 | O11: =N11/((1+$D$1)^((H11-$H$4)/365)) -> 383.05122
A12: 48944 | B12: 0 | C12: 2248.3847 | D12: 676.74194 | E12: 0 | F12: =-B12+C12-D12+E12 -> 1571.6428 | G12: =F12/((1+$B$1)^((A12-$A$4)/365)) -> 1199.8909 | H12: 48944 | I12: 0 | J12: 0 | K12: 104.90991 | L12: 341.79789 | M12: 0 | N12: =-I12-J12+K12+L12+M12 -> 446.7078 | O12: =N12/((1+$D$1)^((H12-$H$4)/365)) -> 283.89088
A13: 49125 | B13: 0 | C13: 2246.1371 | D13: 0 | E13: 0 | F13: =-B13+C13-D13+E13 -> 2246.1371 | G13: =F13/((1+$B$1)^((A13-$A$4)/365)) -> 1650.6297 | H13: 49125 | I13: 0 | J13: 0 | K13: 241.97353 | L13: 336.22509 | M13: 0 | N13: =-I13-J13+K13+L13+M13 -> 578.19862 | O13: =N13/((1+$D$1)^((H13-$H$4)/365)) -> 347.37473
A14: 49309 | B14: 0 | C14: 2283.3658 | D14: 694.09066 | E14: 0 | F14: =-B14+C14-D14+E14 -> 1589.2752 | G14: =F14/((1+$B$1)^((A14-$A$4)/365)) -> 1123.4746 | H14: 49309 | I14: 0 | J14: 0 | K14: 104.81381 | L14: 341.79789 | M14: 0 | N14: =-I14-J14+K14+L14+M14 -> 446.61169 | O14: =N14/((1+$D$1)^((H14-$H$4)/365)) -> 253.41947
A15: 49490 | B15: 0 | C15: 2281.0797 | D15: 0 | E15: 0 | F15: =-B15+C15-D15+E15 -> 2281.0797 | G15: =F15/((1+$B$1)^((A15-$A$4)/365)) -> 1552.1372 | H15: 49490 | I15: 0 | J15: 0 | K15: 251.04247 | L15: 336.22509 | M15: 0 | N15: =-I15-J15+K15+L15+M15 -> 587.26756 | O15: =N15/((1+$D$1)^((H15-$H$4)/365)) -> 315.02075
... A56: 56979 | B56: 0 | C56: 3835.9304 | D56: 1609.5744 | E56: 0 | F56: =-B56+C56-D56+E56 -> 2226.356 | G56: =F56/((1+$B$1)^((A56-$A$4)/365)) -> 312.32163 | H56: 56979 | I56: 0 | J56: 0 | K56: 2226.356 | L56: 0 | M56: 0 | N56: =-I56-J56+K56+L56+M56 -> 2226.356 | O56: =N56/((1+$D$1)^((H56-$H$4)/365)) -> 116.74863

Sheet 2_sol_BANK_Roll
A1: Observation date | B1: Index | C1: Opening Senior | D1: Remaining horizon | E1: Independent LLCR | F1: Persisted ratio | G1: Difference
A2: 47908 | B2: 3 | C2: 26925.862 | D2: 25 | E2: =SUMPRODUCT(('2_sol_BANK_Inputs'!$C$12:$C$61>=B2)*('2_sol_BANK_Inputs'!$C$12:$C$61<=D2)*'2_sol_BANK_Inputs'!$L$12:$L$61/((1+'2_sol_BANK_Inputs'!$B$2)^(('2_sol_BANK_Inputs'!$A$12:$A$61-A2)/365)))/C2 -> 1.2333445 | F2: 1.2333445 | G2: =E2-F2 -> -6.6613381e-16
A3: 48029 | B3: 4 | C3: 26350.119 | D3: 25 | E3: =SUMPRODUCT(('2_sol_BANK_Inputs'!$C$12:$C$61>=B3)*('2_sol_BANK_Inputs'!$C$12:$C$61<=D3)*'2_sol_BANK_Inputs'!$L$12:$L$61/((1+'2_sol_BANK_Inputs'!$B$2)^(('2_sol_BANK_Inputs'!$A$12:$A$61-A3)/365)))/C3 -> 1.2339738 | F3: 1.2339738 | G3: =E3-F3 -> -6.6613381e-16
A4: 48213 | B4: 5 | C4: 25471.804 | D4: 25 | E4: =SUMPRODUCT(('2_sol_BANK_Inputs'!$C$12:$C$61>=B4)*('2_sol_BANK_Inputs'!$C$12:$C$61<=D4)*'2_sol_BANK_Inputs'!$L$12:$L$61/((1+'2_sol_BANK_Inputs'!$B$2)^(('2_sol_BANK_Inputs'!$A$12:$A$61-A4)/365)))/C4 -> 1.2351718 | F4: 1.2351718 | G4: =E4-F4 -> -2.220446e-16
A5: 48395 | B5: 6 | C5: 24558.208 | D5: 25 | E5: =SUMPRODUCT(('2_sol_BANK_Inputs'!$C$12:$C$61>=B5)*('2_sol_BANK_Inputs'!$C$12:$C$61<=D5)*'2_sol_BANK_Inputs'!$L$12:$L$61/((1+'2_sol_BANK_Inputs'!$B$2)^(('2_sol_BANK_Inputs'!$A$12:$A$61-A5)/365)))/C5 -> 1.2365351 | F5: 1.2365351 | G5: =E5-F5 -> -2.220446e-16
A6: 48579 | B6: 7 | C6: 23616.953 | D6: 25 | E6: =SUMPRODUCT(('2_sol_BANK_Inputs'!$C$12:$C$61>=B6)*('2_sol_BANK_Inputs'!$C$12:$C$61<=D6)*'2_sol_BANK_Inputs'!$L$12:$L$61/((1+'2_sol_BANK_Inputs'!$B$2)^(('2_sol_BANK_Inputs'!$A$12:$A$61-A6)/365)))/C6 -> 1.2380908 | F6: 1.2380908 | G6: =E6-F6 -> -2.220446e-16
A7: 48760 | B7: 8 | C7: 22627.571 | D7: 25 | E7: =SUMPRODUCT(('2_sol_BANK_Inputs'!$C$12:$C$61>=B7)*('2_sol_BANK_Inputs'!$C$12:$C$61<=D7)*'2_sol_BANK_Inputs'!$L$12:$L$61/((1+'2_sol_BANK_Inputs'!$B$2)^(('2_sol_BANK_Inputs'!$A$12:$A$61-A7)/365)))/C7 -> 1.2398906 | F7: 1.2398906 | G7: =E7-F7 -> -4.4408921e-16
A8: 48944 | B8: 9 | C8: 21647.001 | D8: 25 | E8: =SUMPRODUCT(('2_sol_BANK_Inputs'!$C$12:$C$61>=B8)*('2_sol_BANK_Inputs'!$C$12:$C$61<=D8)*'2_sol_BANK_Inputs'!$L$12:$L$61/((1+'2_sol_BANK_Inputs'!$B$2)^(('2_sol_BANK_Inputs'!$A$12:$A$61-A8)/365)))/C8 -> 1.2418936 | F8: 1.2418936 | G8: =E8-F8 -> -4.4408921e-16
A9: 49125 | B9: 10 | C9: 20577.663 | D9: 25 | E9: =SUMPRODUCT(('2_sol_BANK_Inputs'!$C$12:$C$61>=B9)*('2_sol_BANK_Inputs'!$C$12:$C$61<=D9)*'2_sol_BANK_Inputs'!$L$12:$L$61/((1+'2_sol_BANK_Inputs'!$B$2)^(('2_sol_BANK_Inputs'!$A$12:$A$61-A9)/365)))/C9 -> 1.2443136 | F9: 1.2443136 | G9: =E9-F9 -> -2.220446e-16
A10: 49309 | B10: 11 | C10: 19549.769 | D10: 25 | E10: =SUMPRODUCT(('2_sol_BANK_Inputs'!$C$12:$C$61>=B10)*('2_sol_BANK_Inputs'!$C$12:$C$61<=D10)*'2_sol_BANK_Inputs'!$L$12:$L$61/((1+'2_sol_BANK_Inputs'!$B$2)^(('2_sol_BANK_Inputs'!$A$12:$A$61-A10)/365)))/C10 -> 1.2469683 | F10: 1.2469683 | G10: =E10-F10 -> -2.220446e-16
A11: 49490 | B11: 12 | C11: 18396.562 | D11: 25 | E11: =SUMPRODUCT(('2_sol_BANK_Inputs'!$C$12:$C$61>=B11)*('2_sol_BANK_Inputs'!$C$12:$C$61<=D11)*'2_sol_BANK_Inputs'!$L$12:$L$61/((1+'2_sol_BANK_Inputs'!$B$2)^(('2_sol_BANK_Inputs'!$A$12:$A$61-A11)/365)))/C11 -> 1.2503032 | F11: 1.2503032 | G11: =E11-F11 -> -2.220446e-16
A12: 49674 | B12: 13 | C12: 17319.297 | D12: 25 | E12: =SUMPRODUCT(('2_sol_BANK_Inputs'!$C$12:$C$61>=B12)*('2_sol_BANK_Inputs'!$C$12:$C$61<=D12)*'2_sol_BANK_Inputs'!$L$12:$L$61/((1+'2_sol_BANK_Inputs'!$B$2)^(('2_sol_BANK_Inputs'!$A$12:$A$61-A12)/365)))/C12 -> 1.2539338 | F12: 1.2539338 | G12: =E12-F12 -> -2.220446e-16
A13: 49856 | B13: 14 | C13: 16076.008 | D13: 25 | E13: =SUMPRODUCT(('2_sol_BANK_Inputs'!$C$12:$C$61>=B13)*('2_sol_BANK_Inputs'!$C$12:$C$61<=D13)*'2_sol_BANK_Inputs'!$L$12:$L$61/((1+'2_sol_BANK_Inputs'!$B$2)^(('2_sol_BANK_Inputs'!$A$12:$A$61-A13)/365)))/C13 -> 1.2587088 | F13: 1.2587088 | G13: =E13-F13 -> -2.220446e-16
... A24: 51866 | B24: 25 | C24: 1274.9554 | D24: 25 | E24: =SUMPRODUCT(('2_sol_BANK_Inputs'!$C$12:$C$61>=B24)*('2_sol_BANK_Inputs'!$C$12:$C$61<=D24)*'2_sol_BANK_Inputs'!$L$12:$L$61/((1+'2_sol_BANK_Inputs'!$B$2)^(('2_sol_BANK_Inputs'!$A$12:$A$61-A24)/365)))/C24 -> 2.1031115 | F24: 2.1031115 | G24: =E24-F24 -> 0

Sheet 3_win_BASE_Inputs
A1: Immutable Run | B1: 20261027T142422605305Z | C1: 37cb0fb5b119e0c07065b92a289050122f6b622ce5e13af115458f8b89fb814c
A2: Coverage rate (annual ratio) | B2: 0.055
A3: Observation date | B3: 48092
A4: Contractual maturity | B4: 53508
A5: Actual extinguishment | B5: 51682
A6: Project life end | B6: 57891
A8: BANK input authority: canonical debt-sizing CFADS; never relabelled P50
A11: End date | B11: Start date | C11: Index | D11: Engine BASE | E11: Engine BANK | F11: Statement EBITDA | G11: Statement FI | H11: Statement cash tax | I11: Rebuilt BASE | J11: BASE difference | K11: Senior opening | L11: Selected CFADS | M11: Discount divisor | N11: Contractual PV | O11: Actual PV | P11: Project-life PV
A12: 48213 | B12: 48092 | C12: 4 | D12: 2139.7301 | E12: 1956.254 | F12: 2269.1963 | G12: 0 | H12: 129.46615 | I12: =F12+G12-H12 -> 2139.7301 | J12: =I12-D12 -> 0 | K12: 36505.158 | L12: =I12 -> 2139.7301 | M12: =(1+$B$2)^((A12-$B$3)/365) -> 1.0179076 | N12: =IF(A12<=$B$4,L12/M12,0) -> 2102.0868 | O12: =IF(A12<=$B$5,L12/M12,0) -> 2102.0868 | P12: =IF(A12<=$B$6,L12/M12,0) -> 2102.0868
A13: 48395 | B13: 48213 | C13: 5 | D13: 3375.9453 | E13: 3011.001 | F13: 3375.9453 | G13: 0 | H13: 0 | I13: =F13+G13-H13 -> 3375.9453 | J13: =I13-D13 -> 0 | K13: 35549.785 | L13: =I13 -> 3375.9453 | M13: =(1+$B$2)^((A13-$B$3)/365) -> 1.0454487 | N13: =IF(A13<=$B$4,L13/M13,0) -> 3229.1831 | O13: =IF(A13<=$B$5,L13/M13,0) -> 3229.1831 | P13: =IF(A13<=$B$6,L13/M13,0) -> 3229.1831
A14: 48579 | B14: 48395 | C14: 6 | D14: 3069.9151 | E14: 2878.0624 | F14: 3492.6569 | G14: 0 | H14: 422.74176 | I14: =F14+G14-H14 -> 3069.9151 | J14: =I14-D14 -> 0 | K14: 34029.099 | L14: =I14 -> 3069.9151 | M14: =(1+$B$2)^((A14-$B$3)/365) -> 1.07405 | N14: =IF(A14<=$B$4,L14/M14,0) -> 2858.2608 | O14: =IF(A14<=$B$5,L14/M14,0) -> 2858.2608 | P14: =IF(A14<=$B$6,L14/M14,0) -> 2858.2608
A15: 48760 | B15: 48579 | C15: 7 | D15: 3445.1243 | E15: 3072.7924 | F15: 3445.1243 | G15: 0 | H15: 0 | I15: =F15+G15-H15 -> 3445.1243 | J15: =I15-D15 -> 0 | K15: 32587.309 | L15: =I15 -> 3445.1243 | M15: =(1+$B$2)^((A15-$B$3)/365) -> 1.1029484 | N15: =IF(A15<=$B$4,L15/M15,0) -> 3123.559 | O15: =IF(A15<=$B$5,L15/M15,0) -> 3123.559 | P15: =IF(A15<=$B$6,L15/M15,0) -> 3123.559
A16: 48944 | B16: 48760 | C16: 8 | D16: 3077.2305 | E16: 2879.9167 | F16: 3583.6539 | G16: 0 | H16: 506.42334 | I16: =F16+G16-H16 -> 3077.2305 | J16: =I16-D16 -> 0 | K16: 30927.778 | L16: =I16 -> 3077.2305 | M16: =(1+$B$2)^((A16-$B$3)/365) -> 1.1331228 | N16: =IF(A16<=$B$4,L16/M16,0) -> 2715.7079 | O16: =IF(A16<=$B$5,L16/M16,0) -> 2715.7079 | P16: =IF(A16<=$B$6,L16/M16,0) -> 2715.7079
A17: 49125 | B17: 48944 | C17: 9 | D17: 3525.2247 | E17: 3144.3264 | F17: 3525.2247 | G17: 0 | H17: 0 | I17: =F17+G17-H17 -> 3525.2247 | J17: =I17-D17 -> 0 | K17: 29397.262 | L17: =I17 -> 3525.2247 | M17: =(1+$B$2)^((A17-$B$3)/365) -> 1.1636105 | N17: =IF(A17<=$B$4,L17/M17,0) -> 3029.5572 | O17: =IF(A17<=$B$5,L17/M17,0) -> 3029.5572 | P17: =IF(A17<=$B$6,L17/M17,0) -> 3029.5572
A18: 49309 | B18: 49125 | C18: 10 | D18: 3073.9755 | E18: 2872.1415 | F18: 3666.7105 | G18: 0 | H18: 592.73504 | I18: =F18+G18-H18 -> 3073.9755 | J18: =I18-D18 -> 0 | K18: 27589.906 | L18: =I18 -> 3073.9755 | M18: =(1+$B$2)^((A18-$B$3)/365) -> 1.1954445 | N18: =IF(A18<=$B$4,L18/M18,0) -> 2571.4078 | O18: =IF(A18<=$B$5,L18/M18,0) -> 2571.4078 | P18: =IF(A18<=$B$6,L18/M18,0) -> 2571.4078
A19: 49490 | B19: 49309 | C19: 11 | D19: 3606.9272 | E19: 3217.2911 | F19: 3606.9272 | G19: 0 | H19: 0 | I19: =F19+G19-H19 -> 3606.9272 | J19: =I19-D19 -> 0 | K19: 25972.038 | L19: =I19 -> 3606.9272 | M19: =(1+$B$2)^((A19-$B$3)/365) -> 1.2276091 | N19: =IF(A19<=$B$4,L19/M19,0) -> 2938.1724 | O19: =IF(A19<=$B$5,L19/M19,0) -> 2938.1724 | P19: =IF(A19<=$B$6,L19/M19,0) -> 2938.1724
A20: 49674 | B20: 49490 | C20: 12 | D20: 3068.2404 | E20: 2861.7944 | F20: 3751.4283 | G20: 0 | H20: 683.18785 | I20: =F20+G20-H20 -> 3068.2404 | J20: =I20-D20 -> 0 | K20: 24009.161 | L20: =I20 -> 3068.2404 | M20: =(1+$B$2)^((A20-$B$3)/365) -> 1.261194 | N20: =IF(A20<=$B$4,L20/M20,0) -> 2432.8061 | O20: =IF(A20<=$B$5,L20/M20,0) -> 2432.8061 | P20: =IF(A20<=$B$6,L20/M20,0) -> 2432.8061
A21: 49856 | B21: 49674 | C21: 13 | D21: 3700.5135 | E21: 3300.8579 | F21: 3700.5135 | G21: 0 | H21: 0 | I21: =F21+G21-H21 -> 3700.5135 | J21: =I21-D21 -> 0 | K21: 22299.256 | L21: =I21 -> 3700.5135 | M21: =(1+$B$2)^((A21-$B$3)/365) -> 1.2953176 | N21: =IF(A21<=$B$4,L21/M21,0) -> 2856.8387 | O21: =IF(A21<=$B$5,L21/M21,0) -> 2856.8387 | P21: =IF(A21<=$B$6,L21/M21,0) -> 2856.8387
A22: 50040 | B22: 49856 | C22: 14 | D22: 2949.1398 | E22: 2739.12 | F22: 3827.3545 | G22: 0 | H22: 878.21472 | I22: =F22+G22-H22 -> 2949.1398 | J22: =I22-D22 -> 0 | K22: 20168.585 | L22: =I22 -> 2949.1398 | M22: =(1+$B$2)^((A22-$B$3)/365) -> 1.3307549 | N22: =IF(A22<=$B$4,L22/M22,0) -> 2216.1405 | O22: =IF(A22<=$B$5,L22/M22,0) -> 2216.1405 | P22: =IF(A22<=$B$6,L22/M22,0) -> 2216.1405
A23: 50221 | B23: 50040 | C23: 15 | D23: 3775.2669 | E23: 3367.6275 | F23: 3775.2669 | G23: 0 | H23: 0 | I23: =F23+G23-H23 -> 3775.2669 | J23: =I23-D23 -> 0 | K23: 18452.946 | L23: =I23 -> 3775.2669 | M23: =(1+$B$2)^((A23-$B$3)/365) -> 1.3665601 | N23: =IF(A23<=$B$4,L23/M23,0) -> 2762.6059 | O23: =IF(A23<=$B$5,L23/M23,0) -> 2762.6059 | P23: =IF(A23<=$B$6,L23/M23,0) -> 2762.6059
... A41: 53508 | B41: 53327 | C41: 33 | D41: 5082.7583 | E41: 4538.4951 | F41: 5082.7583 | G41: 0 | H41: 0 | I41: =F41+G41-H41 -> 5082.7583 | J41: =I41-D41 -> 0 | K41: 0 | L41: =I41 -> 5082.7583 | M41: =(1+$B$2)^((A41-$B$3)/365) -> 2.2132388 | N41: =IF(A41<=$B$4,L41/M41,0) -> 2296.525 | O41: =IF(A41<=$B$5,L41/M41,0) -> 0 | P41: =IF(A41<=$B$6,L41/M41,0) -> 2296.525
A42: 53692 | B42: 53508 | C42: 34 | D42: 3298.6622 | E42: 3010.6284 | F42: 5281.7266 | G42: 0 | H42: 1983.0643 | I42: =F42+G42-H42 -> 3298.6622 | J42: =I42-D42 -> 0 | L42: =I42 -> 3298.6622 | M42: =(1+$B$2)^((A42-$B$3)/365) -> 2.2737885 | N42: =IF(A42<=$B$4,L42/M42,0) -> 0 | O42: =IF(A42<=$B$5,L42/M42,0) -> 0 | P42: =IF(A42<=$B$6,L42/M42,0) -> 1450.734
A43: 53873 | B43: 53692 | C43: 35 | D43: 5195.6115 | E43: 4639.3431 | F43: 5195.6115 | G43: 0 | H43: 0 | I43: =F43+G43-H43 -> 5195.6115 | J43: =I43-D43 -> 0 | L43: =I43 -> 5195.6115 | M43: =(1+$B$2)^((A43-$B$3)/365) -> 2.3349669 | N43: =IF(A43<=$B$4,L43/M43,0) -> 0 | O43: =IF(A43<=$B$5,L43/M43,0) -> 0 | P43: =IF(A43<=$B$6,L43/M43,0) -> 2225.1328
A44: 54057 | B44: 53873 | C44: 36 | D44: 3252.5375 | E44: 2958.1671 | F44: 5398.7447 | G44: 0 | H44: 2146.2072 | I44: =F44+G44-H44 -> 3252.5375 | J44: =I44-D44 -> 0 | L44: =I44 -> 3252.5375 | M44: =(1+$B$2)^((A44-$B$3)/365) -> 2.3988469 | N44: =IF(A44<=$B$4,L44/M44,0) -> 0 | O44: =IF(A44<=$B$5,L44/M44,0) -> 0 | P44: =IF(A44<=$B$6,L44/M44,0) -> 1355.8754
A45: 54239 | B45: 54057 | C45: 37 | D45: 5325.4723 | E45: 4755.3798 | F45: 5325.4723 | G45: 0 | H45: 0 | I45: =F45+G45-H45 -> 5325.4723 | J45: =I45-D45 -> 0 | L45: =I45 -> 5325.4723 | M45: =(1+$B$2)^((A45-$B$3)/365) -> 2.4637515 | N45: =IF(A45<=$B$4,L45/M45,0) -> 0 | O45: =IF(A45<=$B$5,L45/M45,0) -> 0 | P45: =IF(A45<=$B$6,L45/M45,0) -> 2161.5298
A46: 54423 | B46: 54239 | C46: 38 | D46: 3179.6633 | E46: 2880.441 | F46: 5503.0263 | G46: 0 | H46: 2323.3631 | I46: =F46+G46-H46 -> 3179.6633 | J46: =I46-D46 -> 0 | L46: =I46 -> 3179.6633 | M46: =(1+$B$2)^((A46-$B$3)/365) -> 2.5311547 | N46: =IF(A46<=$B$4,L46/M46,0) -> 0 | O46: =IF(A46<=$B$5,L46/M46,0) -> 0 | P46: =IF(A46<=$B$6,L46/M46,0) -> 1256.2106
A47: 54604 | B47: 54423 | C47: 39 | D47: 5428.134 | E47: 4847.1305 | F47: 5428.134 | G47: 0 | H47: 0 | I47: =F47+G47-H47 -> 5428.134 | J47: =I47-D47 -> 0 | L47: =I47 -> 5428.134 | M47: =(1+$B$2)^((A47-$B$3)/365) -> 2.5992578 | N47: =IF(A47<=$B$4,L47/M47,0) -> 0 | O47: =IF(A47<=$B$5,L47/M47,0) -> 0 | P47: =IF(A47<=$B$6,L47/M47,0) -> 2088.34
A48: 54788 | B48: 54604 | C48: 40 | D48: 3247.6876 | E48: 2940.2677 | F48: 5639.8487 | G48: 0 | H48: 2392.1611 | I48: =F48+G48-H48 -> 3247.6876 | J48: =I48-D48 -> 0 | L48: =I48 -> 3247.6876 | M48: =(1+$B$2)^((A48-$B$3)/365) -> 2.6703682 | N48: =IF(A48<=$B$4,L48/M48,0) -> 0 | O48: =IF(A48<=$B$5,L48/M48,0) -> 0 | P48: =IF(A48<=$B$6,L48/M48,0) -> 1216.1947
A49: 54969 | B49: 54788 | C49: 41 | D49: 5547.8947 | E49: 4954.1512 | F49: 5547.8947 | G49: 0 | H49: 0 | I49: =F49+G49-H49 -> 5547.8947 | J49: =I49-D49 -> 0 | L49: =I49 -> 5547.8947 | M49: =(1+$B$2)^((A49-$B$3)/365) -> 2.742217 | N49: =IF(A49<=$B$4,L49/M49,0) -> 0 | O49: =IF(A49<=$B$5,L49/M49,0) -> 0 | P49: =IF(A49<=$B$6,L49/M49,0) -> 2023.1421
A50: 55153 | B50: 54969 | C50: 42 | D50: 3310.8795 | E50: 2996.7375 | F50: 5764.0292 | G50: 0 | H50: 2453.1497 | I50: =F50+G50-H50 -> 3310.8795 | J50: =I50-D50 -> 0 | L50: =I50 -> 3310.8795 | M50: =(1+$B$2)^((A50-$B$3)/365) -> 2.8172385 | N50: =IF(A50<=$B$4,L50/M50,0) -> 0 | O50: =IF(A50<=$B$5,L50/M50,0) -> 0 | P50: =IF(A50<=$B$6,L50/M50,0) -> 1175.2216
A51: 55334 | B51: 55153 | C51: 43 | D51: 5670.0505 | E51: 5063.3124 | F51: 5670.0505 | G51: 0 | H51: 0 | I51: =F51+G51-H51 -> 5670.0505 | J51: =I51-D51 -> 0 | L51: =I51 -> 5670.0505 | M51: =(1+$B$2)^((A51-$B$3)/365) -> 2.893039 | N51: =IF(A51<=$B$4,L51/M51,0) -> 0 | O51: =IF(A51<=$B$5,L51/M51,0) -> 0 | P51: =IF(A51<=$B$6,L51/M51,0) -> 1959.8943
A52: 55518 | B52: 55334 | C52: 44 | D52: 3375.3544 | E52: 3054.3533 | F52: 5890.6934 | G52: 0 | H52: 2515.339 | I52: =F52+G52-H52 -> 3375.3544 | J52: =I52-D52 -> 0 | L52: =I52 -> 3375.3544 | M52: =(1+$B$2)^((A52-$B$3)/365) -> 2.9721866 | N52: =IF(A52<=$B$4,L52/M52,0) -> 0 | O52: =IF(A52<=$B$5,L52/M52,0) -> 0 | P52: =IF(A52<=$B$6,L52/M52,0) -> 1135.6469
A53: 55700 | B53: 55518 | C53: 45 | D53: 5810.7443 | E53: 5189.0296 | F53: 5810.7443 | G53: 0 | H53: 0 | I53: =F53+G53-H53 -> 5810.7443 | J53: =I53-D53 -> 0 | L53: =I53 -> 5810.7443 | M53: =(1+$B$2)^((A53-$B$3)/365) -> 3.0526038 | N53: =IF(A53<=$B$4,L53/M53,0) -> 0 | O53: =IF(A53<=$B$5,L53/M53,0) -> 0 | P53: =IF(A53<=$B$6,L53/M53,0) -> 1903.537
... A65: 57891 | B65: 57710 | C65: 57 | D65: 4993.3632 | E65: 4463.4319 | F65: 6596.3545 | G65: 0 | H65: 1602.9913 | I65: =F65+G65-H65 -> 4993.3632 | J65: =I65-D65 -> 0 | L65: =I65 -> 4993.3632 | M65: =(1+$B$2)^((A65-$B$3)/365) -> 4.2096783 | N65: =IF(A65<=$B$4,L65/M65,0) -> 0 | O65: =IF(A65<=$B$5,L65/M65,0) -> 0 | P65: =IF(A65<=$B$6,L65/M65,0) -> 1186.1626

Sheet 3_win_BASE_CF
A1: Project discount | B1: 0.08 | C1: Sponsor hurdle | D1: 0.12
A3: Project date | B3: Investment | C3: Operating | D3: Tax | E3: Terminal | F3: Rebuilt net project CF | G3: Discounted project CF | H3: Sponsor date | I3: Equity cash out | J3: SHL cash out | K3: Equity distributions | L3: SHL interest | M3: SHL principal | N3: Rebuilt sponsor net CF | O3: Discounted sponsor CF
A4: 47664 | B4: 41200 | C4: 0 | D4: 0 | E4: 0 | F4: =-B4+C4-D4+E4 -> -41200 | G4: =F4/((1+$B$1)^((A4-$A$4)/365)) -> -41200 | H4: 47484 | I4: 500 | J4: 11668.386 | K4: 0 | L4: 0 | M4: 0 | N4: =-I4-J4+K4+L4+M4 -> -12168.386 | O4: =N4/((1+$D$1)^((H4-$H$4)/365)) -> -12168.386
A5: 47848 | B5: 1800 | C5: 0 | D5: 0 | E5: 0 | F5: =-B5+C5-D5+E5 -> -1800 | G5: =F5/((1+$B$1)^((A5-$A$4)/365)) -> -1731.5031 | H5: 47665 | I5: 0 | J5: 0 | K5: 0 | L5: 0 | M5: 0 | N5: =-I5-J5+K5+L5+M5 -> 0 | O5: =N5/((1+$D$1)^((H5-$H$4)/365)) -> 0
A6: 48029 | B6: 0 | C6: 0 | D6: 0 | E6: 0 | F6: =-B6+C6-D6+E6 -> 0 | G6: =F6/((1+$B$1)^((A6-$A$4)/365)) -> 0 | H6: 47849 | I6: 0 | J6: 0 | K6: 0 | L6: 0 | M6: 0 | N6: =-I6-J6+K6+L6+M6 -> 0 | O6: =N6/((1+$D$1)^((H6-$H$4)/365)) -> 0
A7: 48091 | B7: 0 | C7: 0 | D7: 0 | E7: 0 | F7: =-B7+C7-D7+E7 -> 0 | G7: =F7/((1+$B$1)^((A7-$A$4)/365)) -> 0 | H7: 48030 | I7: 0 | J7: 0 | K7: 0 | L7: 0 | M7: 0 | N7: =-I7-J7+K7+L7+M7 -> 0 | O7: =N7/((1+$D$1)^((H7-$H$4)/365)) -> 0
A8: 48213 | B8: 0 | C8: 2269.1963 | D8: 378.17353 | E8: 0 | F8: =-B8+C8-D8+E8 -> 1891.0227 | G8: =F8/((1+$B$1)^((A8-$A$4)/365)) -> 1684.3167 | H8: 48213 | I8: 0 | J8: 0 | K8: 197.50898 | L8: 312.00944 | M8: 0 | N8: =-I8-J8+K8+L8+M8 -> 509.51843 | O8: =N8/((1+$D$1)^((H8-$H$4)/365)) -> 406.31111
A9: 48395 | B9: 0 | C9: 3375.9453 | D9: 0 | E9: 0 | F9: =-B9+C9-D9+E9 -> 3375.9453 | G9: =F9/((1+$B$1)^((A9-$A$4)/365)) -> 2893.7187 | H9: 48395 | I9: 0 | J9: 0 | K9: 402.59278 | L9: 464.18497 | M9: 0 | N9: =-I9-J9+K9+L9+M9 -> 866.77775 | O9: =N9/((1+$D$1)^((H9-$H$4)/365)) -> 653.22826
A10: 48579 | B10: 0 | C10: 3492.6569 | D10: 1142.2674 | E10: 0 | F10: =-B10+C10-D10+E10 -> 2350.3895 | G10: =F10/((1+$B$1)^((A10-$A$4)/365)) -> 1937.9899 | H10: 48579 | I10: 0 | J10: 0 | K10: 202.24385 | L10: 469.28591 | M10: 0 | N10: =-I10-J10+K10+L10+M10 -> 671.52976 | O10: =N10/((1+$D$1)^((H10-$H$4)/365)) -> 477.98162
A11: 48760 | B11: 0 | C11: 3445.1243 | D11: 0 | E11: 0 | F11: =-B11+C11-D11+E11 -> 3445.1243 | G11: =F11/((1+$B$1)^((A11-$A$4)/365)) -> 2734.2741 | H11: 48760 | I11: 0 | J11: 0 | K11: 421.56469 | L11: 462.89926 | M11: 0 | N11: =-I11-J11+K11+L11+M11 -> 884.46395 | O11: =N11/((1+$D$1)^((H11-$H$4)/365)) -> 595.14025
